Workbook

Sheet How to Use
B2: How to Use
B4: Step 1: Set Up Your Cycle
B5: Go to the Setup tab and enter three things: • Cycle Start Date — the first day of your most recent period • Cycle Length — your average cycle length in days (default: 28) • Period Length — how many days your period usually lasts (default: 5) These settings control the dates and stage labels across the whole tracker.
B7: Step 2: Track Your Daily Mood
B8: On the Tracker tab, each month has a Mood row. Click any cell and choose from the dropdown: • Good — you're feeling okay or positive • Okay — manageable, but not great • Low — difficult day, noticeable mood symptoms You don't need to fill every day — even a few entries per cycle help the Dashboard spot patterns.
B10: Step 3: Add Notes (Optional)
B11: Each month also has a Notes row. Use it to jot down anything you want to remember: • Symptoms (headaches, bloating, fatigue, cravings) • Life events that may have affected your mood • Medications or supplements you tried These notes are valuable when you visit your doctor — they turn "I think I feel bad before my period" into specific evidence.
B13: Step 4: Adjust for Irregular Cycles
B14: Your cycles won't always be the same length — that's completely normal. Each month on the Tracker has a Cycle Start date (the first cell on the Date row). By default, it auto-calculates from the previous month + your cycle length. But if your cycle was shorter or longer: • Simply type the actual start date of your new cycle into that cell • The rest of that month's dates will adjust automatically • The next month will chain from your new date Look for the purple note indicator ▾ on each start date cell for a reminder.
B16: Step 5: Check Your Dashboard
B17: The Dashboard tab updates automatically as you track. It shows: • Cycle Summary — how many Good, Okay, and Low days per month • Key Metrics — total days tracked, average low days per cycle, most common low phase • Patterns Across Your Cycles — highlights whether Low mood tends to show up in the late luteal phase and ease off in the follicular phase • Your Patterns So Far — a simple summary of how often that pattern has shown up in your tracked cycles The more cycles you track, the clearer the picture becomes. Two to three cycles is usually enough to start seeing patterns.
B19: Step 6: Understand the Colours
... B25: You've got this 💛

Sheet Setup
B2: Setup
B4: Cycle Start Date | C4: 45858
B5: Cycle Length (days) | C5: 30
B6: Period Length (days) | C6: 5
B8: Edit the values above. The Tracker tab updates automatically.
B10: PHASE REFERENCE | C10: DAYS
B11: Period | C11: ="Days 1–"&C6 -> Days 1–5
B12: Late Follicular | C12: ="Days "&(C6+1)&"–"&(ROUND(C5/2,0)-2) -> Days 6–13
B13: Ovulation | C13: ="Days "&(ROUND(C5/2,0)-1)&"–"&(ROUND(C5/2,0)+1) -> Days 14–16
B14: Mid Luteal | C14: ="Days "&(ROUND(C5/2,0)+2)&"–"&(C5-5) -> Days 17–25
B15: Late Luteal | C15: ="Days "&(C5-4)&"–"&C5 -> Days 26–30
B18: © 2025 dear PMDD™. All rights reserved. Redistribution or resale prohibited without written permission.

Sheet Tracker
E1: Tracker
A2: CYCLE DAY | B2: =IF(1<=$AL$6,1,"") -> 1 | C2: =IF(2<=$AL$6,2,"") -> 2 | D2: =IF(3<=$AL$6,3,"") -> 3 | E2: =IF(4<=$AL$6,4,"") -> 4 | F2: =IF(5<=$AL$6,5,"") -> 5 | G2: =IF(6<=$AL$6,6,"") -> 6 | H2: =IF(7<=$AL$6,7,"") -> 7 | I2: =IF(8<=$AL$6,8,"") -> 8 | J2: =IF(9<=$AL$6,9,"") -> 9 | K2: =IF(10<=$AL$6,10,"") -> 10 | L2: =IF(11<=$AL$6,11,"") -> 11 | M2: =IF(12<=$AL$6,12,"") -> 12 | N2: =IF(13<=$AL$6,13,"") -> 13 | O2: =IF(14<=$AL$6,14,"") -> 14 | P2: =IF(15<=$AL$6,15,"") -> 15 | Q2: =IF(16<=$AL$6,16,"") -> 16 | R2: =IF(17<=$AL$6,17,"") -> 17 | S2: =IF(18<=$AL$6,18,"") -> 18 | T2: =IF(19<=$AL$6,19,"") -> 19 | U2: =IF(20<=$AL$6,20,"") -> 20 | V2: =IF(21<=$AL$6,21,"") -> 21 | W2: =IF(22<=$AL$6,22,"") -> 22 | X2: =IF(23<=$AL$6,23,"") -> 23 | Y2: =IF(24<=$AL$6,24,"") -> 24 | Z2: =IF(25<=$AL$6,25,"") -> 25 | AA2: =IF(26<=$AL$6,26,"") -> 26 | AB2: =IF(27<=$AL$6,27,"") -> 27 | AC2: =IF(28<=$AL$6,28,"") -> 28 | AD2: =IF(29<=$AL$6,29,"") | AE2: =IF(30<=$AL$6,30,"") | AF2: =IF(31<=$AL$6,31,"") | AG2: =IF(32<=$AL$6,32,"") | AH2: =IF(33<=$AL$6,33,"") | AI2: =IF(34<=$AL$6,34,"") | AJ2: =IF(35<=$AL$6,35,"")
A3: STAGE | B3: =IF(1>$AL$6,"",IF(1<=$AM$6,"Period",IF(1<ROUND($AL$6/2,0)-1,"Follicular",IF(1<=ROUND($AL$6/2,0)+1,"Ovulation",IF(1<=$AL$6-5,"Mid Luteal","Late Luteal"))))) -> Period | C3: =IF(2>$AL$6,"",IF(2<=$AM$6,"Period",IF(2<ROUND($AL$6/2,0)-1,"Follicular",IF(2<=ROUND($AL$6/2,0)+1,"Ovulation",IF(2<=$AL$6-5,"Mid Luteal","Late Luteal"))))) -> Period | D3: =IF(3>$AL$6,"",IF(3<=$AM$6,"Period",IF(3<ROUND($AL$6/2,0)-1,"Follicular",IF(3<=ROUND($AL$6/2,0)+1,"Ovulation",IF(3<=$AL$6-5,"Mid Luteal","Late Luteal"))))) -> Period | E3: =IF(4>$AL$6,"",IF(4<=$AM$6,"Period",IF(4<ROUND($AL$6/2,0)-1,"Follicular",IF(4<=ROUND($AL$6/2,0)+1,"Ovulation",IF(4<=$AL$6-5,"Mid Luteal","Late Luteal"))))) -> Period | F3: =IF(5>$AL$6,"",IF(5<=$AM$6,"Period",IF(5<ROUND($AL$6/2,0)-1,"Follicular",IF(5<=ROUND($AL$6/2,0)+1,"Ovulation",IF(5<=$AL$6-5,"Mid Luteal","Late Luteal"))))) -> Period | G3: =IF(6>$AL$6,"",IF(6<=$AM$6,"Period",IF(6<ROUND($AL$6/2,0)-1,"Follicular",IF(6<=ROUND($AL$6/2,0)+1,"Ovulation",IF(6<=$AL$6-5,"Mid Luteal","Late Luteal"))))) -> Follicular | H3: =IF(7>$AL$6,"",IF(7<=$AM$6,"Period",IF(7<ROUND($AL$6/2,0)-1,"Follicular",IF(7<=ROUND($AL$6/2,0)+1,"Ovulation",IF(7<=$AL$6-5,"Mid Luteal","Late Luteal"))))) -> Follicular | I3: =IF(8>$AL$6,"",IF(8<=$AM$6,"Period",IF(8<ROUND($AL$6/2,0)-1,"Follicular",IF(8<=ROUND($AL$6/2,0)+1,"Ovulation",IF(8<=$AL$6-5,"Mid Luteal","Late Luteal"))))) -> Follicular | J3: =IF(9>$AL$6,"",IF(9<=$AM$6,"Period",IF(9<ROUND($AL$6/2,0)-1,"Follicular",IF(9<=ROUND($AL$6/2,0)+1,"Ovulation",IF(9<=$AL$6-5,"Mid Luteal","Late Luteal"))))) -> Follicular | K3: =IF(10>$AL$6,"",IF(10<=$AM$6,"Period",IF(10<ROUND($AL$6/2,0)-1,"Follicular",IF(10<=ROUND($AL$6/2,0)+1,"Ovulation",IF(10<=$AL$6-5,"Mid Luteal","Late Luteal"))))) -> Follicular | L3: =IF(11>$AL$6,"",IF(11<=$AM$6,"Period",IF(11<ROUND($AL$6/2,0)-1,"Follicular",IF(11<=ROUND($AL$6/2,0)+1,"Ovulation",IF(11<=$AL$6-5,"Mid Luteal","Late Luteal"))))) -> Follicular | M3: =IF(12>$AL$6,"",IF(12<=$AM$6,"Period",IF(12<ROUND($AL$6/2,0)-1,"Follicular",IF(12<=ROUND($AL$6/2,0)+1,"Ovulation",IF(12<=$AL$6-5,"Mid Luteal","Late Luteal"))))) -> Follicular | N3: =IF(13>$AL$6,"",IF(13<=$AM$6,"Period",IF(13<ROUND($AL$6/2,0)-1,"Follicular",IF(13<=ROUND($AL$6/2,0)+1,"Ovulation",IF(13<=$AL$6-5,"Mid Luteal","Late Luteal"))))) -> Ovulation | O3: =IF(14>$AL$6,"",IF(14<=$AM$6,"Period",IF(14<ROUND($AL$6/2,0)-1,"Follicular",IF(14<=ROUND($AL$6/2,0)+1,"Ovulation",IF(14<=$AL$6-5,"Mid Luteal","Late Luteal"))))) -> Ovulation | P3: =IF(15>$AL$6,"",IF(15<=$AM$6,"Period",IF(15<ROUND($AL$6/2,0)-1,"Follicular",IF(15<=ROUND($AL$6/2,0)+1,"Ovulation",IF(15<=$AL$6-5,"Mid Luteal","Late Luteal"))))) -> Ovulation | Q3: =IF(16>$AL$6,"",IF(16<=$AM$6,"Period",IF(16<ROUND($AL$6/2,0)-1,"Follicular",IF(16<=ROUND($AL$6/2,0)+1,"Ovulation",IF(16<=$AL$6-5,"Mid Luteal","Late Luteal"))))) -> Mid Luteal | R3: =IF(17>$AL$6,"",IF(17<=$AM$6,"Period",IF(17<ROUND($AL$6/2,0)-1,"Follicular",IF(17<=ROUND($AL$6/2,0)+1,"Ovulation",IF(17<=$AL$6-5,"Mid Luteal","Late Luteal"))))) -> Mid Luteal | S3: =IF(18>$AL$6,"",IF(18<=$AM$6,"Period",IF(18<ROUND($AL$6/2,0)-1,"Follicular",IF(18<=ROUND($AL$6/2,0)+1,"Ovulation",IF(18<=$AL$6-5,"Mid Luteal","Late Luteal"))))) -> Mid Luteal | T3: =IF(19>$AL$6,"",IF(19<=$AM$6,"Period",IF(19<ROUND($AL$6/2,0)-1,"Follicular",IF(19<=ROUND($AL$6/2,0)+1,"Ovulation",IF(19<=$AL$6-5,"Mid Luteal","Late Luteal"))))) -> Mid Luteal | U3: =IF(20>$AL$6,"",IF(20<=$AM$6,"Period",IF(20<ROUND($AL$6/2,0)-1,"Follicular",IF(20<=ROUND($AL$6/2,0)+1,"Ovulation",IF(20<=$AL$6-5,"Mid Luteal","Late Luteal"))))) -> Mid Luteal | V3: =IF(21>$AL$6,"",IF(21<=$AM$6,"Period",IF(21<ROUND($AL$6/2,0)-1,"Follicular",IF(21<=ROUND($AL$6/2,0)+1,"Ovulation",IF(21<=$AL$6-5,"Mid Luteal","Late Luteal"))))) -> Mid Luteal | W3: =IF(22>$AL$6,"",IF(22<=$AM$6,"Period",IF(22<ROUND($AL$6/2,0)-1,"Follicular",IF(22<=ROUND($AL$6/2,0)+1,"Ovulation",IF(22<=$AL$6-5,"Mid Luteal","Late Luteal"))))) -> Mid Luteal | X3: =IF(23>$AL$6,"",IF(23<=$AM$6,"Period",IF(23<ROUND($AL$6/2,0)-1,"Follicular",IF(23<=ROUND($AL$6/2,0)+1,"Ovulation",IF(23<=$AL$6-5,"Mid Luteal","Late Luteal"))))) -> Mid Luteal | Y3: =IF(24>$AL$6,"",IF(24<=$AM$6,"Period",IF(24<ROUND($AL$6/2,0)-1,"Follicular",IF(24<=ROUND($AL$6/2,0)+1,"Ovulation",IF(24<=$AL$6-5,"Mid Luteal","Late Luteal"))))) -> Late Luteal | Z3: =IF(25>$AL$6,"",IF(25<=$AM$6,"Period",IF(25<ROUND($AL$6/2,0)-1,"Follicular",IF(25<=ROUND($AL$6/2,0)+1,"Ovulation",IF(25<=$AL$6-5,"Mid Luteal","Late Luteal"))))) -> Late Luteal | AA3: =IF(26>$AL$6,"",IF(26<=$AM$6,"Period",IF(26<ROUND($AL$6/2,0)-1,"Follicular",IF(26<=ROUND($AL$6/2,0)+1,"Ovulation",IF(26<=$AL$6-5,"Mid Luteal","Late Luteal"))))) -> Late Luteal | AB3: =IF(27>$AL$6,"",IF(27<=$AM$6,"Period",IF(27<ROUND($AL$6/2,0)-1,"Follicular",IF(27<=ROUND($AL$6/2,0)+1,"Ovulation",IF(27<=$AL$6-5,"Mid Luteal","Late Luteal"))))) -> Late Luteal | AC3: =IF(28>$AL$6,"",IF(28<=$AM$6,"Period",IF(28<ROUND($AL$6/2,0)-1,"Follicular",IF(28<=ROUND($AL$6/2,0)+1,"Ovulation",IF(28<=$AL$6-5,"Mid Luteal","Late Luteal"))))) -> Late Luteal | AD3: =IF(29>$AL$6,"",IF(29<=$AM$6,"Period",IF(29<ROUND($AL$6/2,0)-1,"Follicular",IF(29<=ROUND($AL$6/2,0)+1,"Ovulation",IF(29<=$AL$6-5,"Mid Luteal","Late Luteal"))))) | AE3: =IF(30>$AL$6,"",IF(30<=$AM$6,"Period",IF(30<ROUND($AL$6/2,0)-1,"Follicular",IF(30<=ROUND($AL$6/2,0)+1,"Ovulation",IF(30<=$AL$6-5,"Mid Luteal","Late Luteal"))))) | AF3: =IF(31>$AL$6,"",IF(31<=$AM$6,"Period",IF(31<ROUND($AL$6/2,0)-1,"Follicular",IF(31<=ROUND($AL$6/2,0)+1,"Ovulation",IF(31<=$AL$6-5,"Mid Luteal","Late Luteal"))))) | AG3: =IF(32>$AL$6,"",IF(32<=$AM$6,"Period",IF(32<ROUND($AL$6/2,0)-1,"Follicular",IF(32<=ROUND($AL$6/2,0)+1,"Ovulation",IF(32<=$AL$6-5,"Mid Luteal","Late Luteal"))))) | AH3: =IF(33>$AL$6,"",IF(33<=$AM$6,"Period",IF(33<ROUND($AL$6/2,0)-1,"Follicular",IF(33<=ROUND($AL$6/2,0)+1,"Ovulation",IF(33<=$AL$6-5,"Mid Luteal","Late Luteal"))))) | AI3: =IF(34>$AL$6,"",IF(34<=$AM$6,"Period",IF(34<ROUND($AL$6/2,0)-1,"Follicular",IF(34<=ROUND($AL$6/2,0)+1,"Ovulation",IF(34<=$AL$6-5,"Mid Luteal","Late Luteal"))))) | AJ3: =IF(35>$AL$6,"",IF(35<=$AM$6,"Period",IF(35<ROUND($AL$6/2,0)-1,"Follicular",IF(35<=ROUND($AL$6/2,0)+1,"Ovulation",IF(35<=$AL$6-5,"Mid Luteal","Late Luteal")))))
A5: MONTH | B5: Jan | AL5: LENGTH | AM5: PERIOD
A6: Cycle Start | B6: =Setup!$C$4 -> 45858 | C6: =IF(2<=$AL$6,B6+1,"") -> 45859 | D6: =IF(3<=$AL$6,C6+1,"") -> 45860 | E6: =IF(4<=$AL$6,D6+1,"") -> 45861 | F6: =IF(5<=$AL$6,E6+1,"") -> 45862 | G6: =IF(6<=$AL$6,F6+1,"") -> 45863 | H6: =IF(7<=$AL$6,G6+1,"") -> 45864 | I6: =IF(8<=$AL$6,H6+1,"") -> 45865 | J6: =IF(9<=$AL$6,I6+1,"") -> 45866 | K6: =IF(10<=$AL$6,J6+1,"") -> 45867 | L6: =IF(11<=$AL$6,K6+1,"") -> 45868 | M6: =IF(12<=$AL$6,L6+1,"") -> 45869 | N6: =IF(13<=$AL$6,M6+1,"") -> 45870 | O6: =IF(14<=$AL$6,N6+1,"") -> 45871 | P6: =IF(15<=$AL$6,O6+1,"") -> 45872 | Q6: =IF(16<=$AL$6,P6+1,"") -> 45873 | R6: =IF(17<=$AL$6,Q6+1,"") -> 45874 | S6: =IF(18<=$AL$6,R6+1,"") -> 45875 | T6: =IF(19<=$AL$6,S6+1,"") -> 45876 | U6: =IF(20<=$AL$6,T6+1,"") -> 45877 | V6: =IF(21<=$AL$6,U6+1,"") -> 45878 | W6: =IF(22<=$AL$6,V6+1,"") -> 45879 | X6: =IF(23<=$AL$6,W6+1,"") -> 45880 | Y6: =IF(24<=$AL$6,X6+1,"") -> 45881 | Z6: =IF(25<=$AL$6,Y6+1,"") -> 45882 | AA6: =IF(26<=$AL$6,Z6+1,"") -> 45883 | AB6: =IF(27<=$AL$6,AA6+1,"") -> 45884 | AC6: =IF(28<=$AL$6,AB6+1,"") -> 45885 | AD6: =IF(29<=$AL$6,AC6+1,"") | AE6: =IF(30<=$AL$6,AD6+1,"") | AF6: =IF(31<=$AL$6,AE6+1,"") | AG6: =IF(32<=$AL$6,AF6+1,"") | AH6: =IF(33<=$AL$6,AG6+1,"") | AI6: =IF(34<=$AL$6,AH6+1,"") | AJ6: =IF(35<=$AL$6,AI6+1,"") | AL6: 28 | AM6: =Setup!$C$6 -> 5
A7: Mood | B7: Good | C7: Okay | D7: Low | O7: Okay | P7: Okay | Q7: Okay | R7: Low | S7: Low | T7: Low
A8: Notes
A10: MONTH | B10: {=INDEX({"Jan","Feb","Mar","Apr","May","Jun","Jul","Aug","Sep","Oct","Nov","Dec"},MOD(MATCH(B5,{"Jan","Feb","Mar","Apr","May","Jun","Jul","Aug","Sep","Oct","Nov","Dec"},0),12)+1)} -> Feb | AL10: LENGTH | AM10: PERIOD
A11: Cycle Start | B11: =$B$6+$AL$6 -> 45886 | C11: =IF(2<=$AL$11,B11+1,"") -> 45887 | D11: =IF(3<=$AL$11,C11+1,"") -> 45888 | E11: =IF(4<=$AL$11,D11+1,"") -> 45889 | F11: =IF(5<=$AL$11,E11+1,"") -> 45890 | G11: =IF(6<=$AL$11,F11+1,"") -> 45891 | H11: =IF(7<=$AL$11,G11+1,"") -> 45892 | I11: =IF(8<=$AL$11,H11+1,"") -> 45893 | J11: =IF(9<=$AL$11,I11+1,"") -> 45894 | K11: =IF(10<=$AL$11,J11+1,"") -> 45895 | L11: =IF(11<=$AL$11,K11+1,"") -> 45896 | M11: =IF(12<=$AL$11,L11+1,"") -> 45897 | N11: =IF(13<=$AL$11,M11+1,"") -> 45898 | O11: =IF(14<=$AL$11,N11+1,"") -> 45899 | P11: =IF(15<=$AL$11,O11+1,"") -> 45900 | Q11: =IF(16<=$AL$11,P11+1,"") -> 45901 | R11: =IF(17<=$AL$11,Q11+1,"") -> 45902 | S11: =IF(18<=$AL$11,R11+1,"") -> 45903 | T11: =IF(19<=$AL$11,S11+1,"") -> 45904 | U11: =IF(20<=$AL$11,T11+1,"") -> 45905 | V11: =IF(21<=$AL$11,U11+1,"") -> 45906 | W11: =IF(22<=$AL$11,V11+1,"") -> 45907 | X11: =IF(23<=$AL$11,W11+1,"") -> 45908 | Y11: =IF(24<=$AL$11,X11+1,"") -> 45909 | Z11: =IF(25<=$AL$11,Y11+1,"") -> 45910 | AA11: =IF(26<=$AL$11,Z11+1,"") -> 45911 | AB11: =IF(27<=$AL$11,AA11+1,"") -> 45912 | AC11: =IF(28<=$AL$11,AB11+1,"") -> 45913 | AD11: =IF(29<=$AL$11,AC11+1,"") -> 45914 | AE11: =IF(30<=$AL$11,AD11+1,"") -> 45915 | AF11: =IF(31<=$AL$11,AE11+1,"") | AG11: =IF(32<=$AL$11,AF11+1,"") | AH11: =IF(33<=$AL$11,AG11+1,"") | AI11: =IF(34<=$AL$11,AH11+1,"") | AJ11: =IF(35<=$AL$11,AI11+1,"") | AL11: =Setup!$C$5 -> 30 | AM11: =Setup!$C$6 -> 5
A12: Mood | U12: Low | AA12: Low
A13: Notes
A15: MONTH | B15: {=INDEX({"Jan","Feb","Mar","Apr","May","Jun","Jul","Aug","Sep","Oct","Nov","Dec"},MOD(MATCH(B10,{"Jan","Feb","Mar","Apr","May","Jun","Jul","Aug","Sep","Oct","Nov","Dec"},0),12)+1)} -> Mar | AL15: LENGTH | AM15: PERIOD
A16: Cycle Start | B16: =$B$11+$AL$11 -> 45916 | C16: =IF(2<=$AL$16,B16+1,"") -> 45917 | D16: =IF(3<=$AL$16,C16+1,"") -> 45918 | E16: =IF(4<=$AL$16,D16+1,"") -> 45919 | F16: =IF(5<=$AL$16,E16+1,"") -> 45920 | G16: =IF(6<=$AL$16,F16+1,"") -> 45921 | H16: =IF(7<=$AL$16,G16+1,"") -> 45922 | I16: =IF(8<=$AL$16,H16+1,"") -> 45923 | J16: =IF(9<=$AL$16,I16+1,"") -> 45924 | K16: =IF(10<=$AL$16,J16+1,"") -> 45925 | L16: =IF(11<=$AL$16,K16+1,"") -> 45926 | M16: =IF(12<=$AL$16,L16+1,"") -> 45927 | N16: =IF(13<=$AL$16,M16+1,"") -> 45928 | O16: =IF(14<=$AL$16,N16+1,"") -> 45929 | P16: =IF(15<=$AL$16,O16+1,"") -> 45930 | Q16: =IF(16<=$AL$16,P16+1,"") -> 45931 | R16: =IF(17<=$AL$16,Q16+1,"") -> 45932 | S16: =IF(18<=$AL$16,R16+1,"") -> 45933 | T16: =IF(19<=$AL$16,S16+1,"") -> 45934 | U16: =IF(20<=$AL$16,T16+1,"") -> 45935 | V16: =IF(21<=$AL$16,U16+1,"") -> 45936 | W16: =IF(22<=$AL$16,V16+1,"") -> 45937 | X16: =IF(23<=$AL$16,W16+1,"") -> 45938 | Y16: =IF(24<=$AL$16,X16+1,"") -> 45939 | Z16: =IF(25<=$AL$16,Y16+1,"") -> 45940 | AA16: =IF(26<=$AL$16,Z16+1,"") -> 45941 | AB16: =IF(27<=$AL$16,AA16+1,"") -> 45942 | AC16: =IF(28<=$AL$16,AB16+1,"") -> 45943 | AD16: =IF(29<=$AL$16,AC16+1,"") -> 45944 | AE16: =IF(30<=$AL$16,AD16+1,"") -> 45945 | AF16: =IF(31<=$AL$16,AE16+1,"") | AG16: =IF(32<=$AL$16,AF16+1,"") | AH16: =IF(33<=$AL$16,AG16+1,"") | AI16: =IF(34<=$AL$16,AH16+1,"") | AJ16: =IF(35<=$AL$16,AI16+1,"") | AL16: =Setup!$C$5 -> 30 | AM16: =Setup!$C$6 -> 5
A17: Mood | U17: Low | Y17: Low
A18: Notes
A20: MONTH | B20: {=INDEX({"Jan","Feb","Mar","Apr","May","Jun","Jul","Aug","Sep","Oct","Nov","Dec"},MOD(MATCH(B15,{"Jan","Feb","Mar","Apr","May","Jun","Jul","Aug","Sep","Oct","Nov","Dec"},0),12)+1)} -> Apr | AL20: LENGTH | AM20: PERIOD
A21: Cycle Start | B21: =$B$16+$AL$16 -> 45946 | C21: =IF(2<=$AL$21,B21+1,"") -> 45947 | D21: =IF(3<=$AL$21,C21+1,"") -> 45948 | E21: =IF(4<=$AL$21,D21+1,"") -> 45949 | F21: =IF(5<=$AL$21,E21+1,"") -> 45950 | G21: =IF(6<=$AL$21,F21+1,"") -> 45951 | H21: =IF(7<=$AL$21,G21+1,"") -> 45952 | I21: =IF(8<=$AL$21,H21+1,"") -> 45953 | J21: =IF(9<=$AL$21,I21+1,"") -> 45954 | K21: =IF(10<=$AL$21,J21+1,"") -> 45955 | L21: =IF(11<=$AL$21,K21+1,"") -> 45956 | M21: =IF(12<=$AL$21,L21+1,"") -> 45957 | N21: =IF(13<=$AL$21,M21+1,"") -> 45958 | O21: =IF(14<=$AL$21,N21+1,"") -> 45959 | P21: =IF(15<=$AL$21,O21+1,"") -> 45960 | Q21: =IF(16<=$AL$21,P21+1,"") -> 45961 | R21: =IF(17<=$AL$21,Q21+1,"") -> 45962 | S21: =IF(18<=$AL$21,R21+1,"") -> 45963 | T21: =IF(19<=$AL$21,S21+1,"") -> 45964 | U21: =IF(20<=$AL$21,T21+1,"") -> 45965 | V21: =IF(21<=$AL$21,U21+1,"") -> 45966 | W21: =IF(22<=$AL$21,V21+1,"") -> 45967 | X21: =IF(23<=$AL$21,W21+1,"") -> 45968 | Y21: =IF(24<=$AL$21,X21+1,"") -> 45969 | Z21: =IF(25<=$AL$21,Y21+1,"") -> 45970 | AA21: =IF(26<=$AL$21,Z21+1,"") -> 45971 | AB21: =IF(27<=$AL$21,AA21+1,"") -> 45972 | AC21: =IF(28<=$AL$21,AB21+1,"") -> 45973 | AD21: =IF(29<=$AL$21,AC21+1,"") -> 45974 | AE21: =IF(30<=$AL$21,AD21+1,"") -> 45975 | AF21: =IF(31<=$AL$21,AE21+1,"") | AG21: =IF(32<=$AL$21,AF21+1,"") | AH21: =IF(33<=$AL$21,AG21+1,"") | AI21: =IF(34<=$AL$21,AH21+1,"") | AJ21: =IF(35<=$AL$21,AI21+1,"") | AL21: =Setup!$C$5 -> 30 | AM21: =Setup!$C$6 -> 5
A22: Mood | U22: Low | V22: Low | W22: Low | X22: Low | Y22: Low
A23: Notes
A25: MONTH | B25: {=INDEX({"Jan","Feb","Mar","Apr","May","Jun","Jul","Aug","Sep","Oct","Nov","Dec"},MOD(MATCH(B20,{"Jan","Feb","Mar","Apr","May","Jun","Jul","Aug","Sep","Oct","Nov","Dec"},0),12)+1)} -> May | AL25: LENGTH | AM25: PERIOD
A26: Cycle Start | B26: =$B$21+$AL$21 -> 45976 | C26: =IF(2<=$AL$26,B26+1,"") -> 45977 | D26: =IF(3<=$AL$26,C26+1,"") -> 45978 | E26: =IF(4<=$AL$26,D26+1,"") -> 45979 | F26: =IF(5<=$AL$26,E26+1,"") -> 45980 | G26: =IF(6<=$AL$26,F26+1,"") -> 45981 | H26: =IF(7<=$AL$26,G26+1,"") -> 45982 | I26: =IF(8<=$AL$26,H26+1,"") -> 45983 | J26: =IF(9<=$AL$26,I26+1,"") -> 45984 | K26: =IF(10<=$AL$26,J26+1,"") -> 45985 | L26: =IF(11<=$AL$26,K26+1,"") -> 45986 | M26: =IF(12<=$AL$26,L26+1,"") -> 45987 | N26: =IF(13<=$AL$26,M26+1,"") -> 45988 | O26: =IF(14<=$AL$26,N26+1,"") -> 45989 | P26: =IF(15<=$AL$26,O26+1,"") -> 45990 | Q26: =IF(16<=$AL$26,P26+1,"") -> 45991 | R26: =IF(17<=$AL$26,Q26+1,"") -> 45992 | S26: =IF(18<=$AL$26,R26+1,"") -> 45993 | T26: =IF(19<=$AL$26,S26+1,"") -> 45994 | U26: =IF(20<=$AL$26,T26+1,"") -> 45995 | V26: =IF(21<=$AL$26,U26+1,"") -> 45996 | W26: =IF(22<=$AL$26,V26+1,"") -> 45997 | X26: =IF(23<=$AL$26,W26+1,"") -> 45998 | Y26: =IF(24<=$AL$26,X26+1,"") -> 45999 | Z26: =IF(25<=$AL$26,Y26+1,"") -> 46000 | AA26: =IF(26<=$AL$26,Z26+1,"") -> 46001 | AB26: =IF(27<=$AL$26,AA26+1,"") -> 46002 | AC26: =IF(28<=$AL$26,AB26+1,"") -> 46003 | AD26: =IF(29<=$AL$26,AC26+1,"") -> 46004 | AE26: =IF(30<=$AL$26,AD26+1,"") -> 46005 | AF26: =IF(31<=$AL$26,AE26+1,"") | AG26: =IF(32<=$AL$26,AF26+1,"") | AH26: =IF(33<=$AL$26,AG26+1,"") | AI26: =IF(34<=$AL$26,AH26+1,"") | AJ26: =IF(35<=$AL$26,AI26+1,"") | AL26: =Setup!$C$5 -> 30 | AM26: =Setup!$C$6 -> 5
A27: Mood
A28: Notes
A30: MONTH | B30: {=INDEX({"Jan","Feb","Mar","Apr","May","Jun","Jul","Aug","Sep","Oct","Nov","Dec"},MOD(MATCH(B25,{"Jan","Feb","Mar","Apr","May","Jun","Jul","Aug","Sep","Oct","Nov","Dec"},0),12)+1)} -> Jun
A31: Cycle Start | B31: =B26+Setup!$C$5 -> 46006 | C31: =IF(COLUMN()-1<=Setup!$C$5,B31+1,"") -> 46007 | D31: =IF(COLUMN()-1<=Setup!$C$5,C31+1,"") -> 46008 | E31: =IF(COLUMN()-1<=Setup!$C$5,D31+1,"") -> 46009 | F31: =IF(COLUMN()-1<=Setup!$C$5,E31+1,"") -> 46010 | G31: =IF(COLUMN()-1<=Setup!$C$5,F31+1,"") -> 46011 | H31: =IF(COLUMN()-1<=Setup!$C$5,G31+1,"") -> 46012 | I31: =IF(COLUMN()-1<=Setup!$C$5,H31+1,"") -> 46013 | J31: =IF(COLUMN()-1<=Setup!$C$5,I31+1,"") -> 46014 | ... AF31: =IF(COLUMN()-1<=Setup!$C$5,AE31+1,"")
A32: Mood | S32: Good
A33: Notes
A35: MONTH | B35: {=INDEX({"Jan","Feb","Mar","Apr","May","Jun","Jul","Aug","Sep","Oct","Nov","Dec"},MOD(MATCH(B30,{"Jan","Feb","Mar","Apr","May","Jun","Jul","Aug","Sep","Oct","Nov","Dec"},0),12)+1)} -> Jul
A36: Cycle Start | B36: =B31+Setup!$C$5 -> 46036 | C36: =IF(COLUMN()-1<=Setup!$C$5,B36+1,"") -> 46037 | D36: =IF(COLUMN()-1<=Setup!$C$5,C36+1,"") -> 46038 | E36: =IF(COLUMN()-1<=Setup!$C$5,D36+1,"") -> 46039 | F36: =IF(COLUMN()-1<=Setup!$C$5,E36+1,"") -> 46040 | G36: =IF(COLUMN()-1<=Setup!$C$5,F36+1,"") -> 46041 | H36: =IF(COLUMN()-1<=Setup!$C$5,G36+1,"") -> 46042 | I36: =IF(COLUMN()-1<=Setup!$C$5,H36+1,"") -> 46043 | J36: =IF(COLUMN()-1<=Setup!$C$5,I36+1,"") -> 46044 | ... AF36: =IF(COLUMN()-1<=Setup!$C$5,AE36+1,"")
A37: Mood
A38: Notes
A40: MONTH | B40: {=INDEX({"Jan","Feb","Mar","Apr","May","Jun","Jul","Aug","Sep","Oct","Nov","Dec"},MOD(MATCH(B35,{"Jan","Feb","Mar","Apr","May","Jun","Jul","Aug","Sep","Oct","Nov","Dec"},0),12)+1)} -> Aug
A41: Cycle Start | B41: =B36+Setup!$C$5 -> 46066 | C41: =IF(COLUMN()-1<=Setup!$C$5,B41+1,"") -> 46067 | D41: =IF(COLUMN()-1<=Setup!$C$5,C41+1,"") -> 46068 | E41: =IF(COLUMN()-1<=Setup!$C$5,D41+1,"") -> 46069 | F41: =IF(COLUMN()-1<=Setup!$C$5,E41+1,"") -> 46070 | G41: =IF(COLUMN()-1<=Setup!$C$5,F41+1,"") -> 46071 | H41: =IF(COLUMN()-1<=Setup!$C$5,G41+1,"") -> 46072 | I41: =IF(COLUMN()-1<=Setup!$C$5,H41+1,"") -> 46073 | J41: =IF(COLUMN()-1<=Setup!$C$5,I41+1,"") -> 46074 | ... AF41: =IF(COLUMN()-1<=Setup!$C$5,AE41+1,"")
A42: Mood
A43: Notes
A45: MONTH | B45: {=INDEX({"Jan","Feb","Mar","Apr","May","Jun","Jul","Aug","Sep","Oct","Nov","Dec"},MOD(MATCH(B40,{"Jan","Feb","Mar","Apr","May","Jun","Jul","Aug","Sep","Oct","Nov","Dec"},0),12)+1)} -> Sep
A46: Cycle Start | B46: =B41+Setup!$C$5 -> 46096 | C46: =IF(COLUMN()-1<=Setup!$C$5,B46+1,"") -> 46097 | D46: =IF(COLUMN()-1<=Setup!$C$5,C46+1,"") -> 46098 | E46: =IF(COLUMN()-1<=Setup!$C$5,D46+1,"") -> 46099 | F46: =IF(COLUMN()-1<=Setup!$C$5,E46+1,"") -> 46100 | G46: =IF(COLUMN()-1<=Setup!$C$5,F46+1,"") -> 46101 | H46: =IF(COLUMN()-1<=Setup!$C$5,G46+1,"") -> 46102 | I46: =IF(COLUMN()-1<=Setup!$C$5,H46+1,"") -> 46103 | J46: =IF(COLUMN()-1<=Setup!$C$5,I46+1,"") -> 46104 | ... AF46: =IF(COLUMN()-1<=Setup!$C$5,AE46+1,"")
A47: Mood
A48: Notes
A50: MONTH | B50: {=INDEX({"Jan","Feb","Mar","Apr","May","Jun","Jul","Aug","Sep","Oct","Nov","Dec"},MOD(MATCH(B45,{"Jan","Feb","Mar","Apr","May","Jun","Jul","Aug","Sep","Oct","Nov","Dec"},0),12)+1)} -> Oct
...

Sheet Dashboard
A1: Dashboard
A3: CYCLE SUMMARY | O3: KEY METRICS
A4: Month | B4: =Tracker!B5 -> Jan | C4: =Tracker!B10 -> Feb | D4: =Tracker!B15 -> Mar | E4: =Tracker!B20 -> Apr | F4: =Tracker!B25 -> May | G4: =Tracker!B30 -> Jun | H4: =Tracker!B35 -> Jul | I4: =Tracker!B40 -> Aug | J4: =Tracker!B45 -> Sep | K4: =Tracker!B50 -> Oct | L4: =Tracker!B55 -> Nov | M4: =Tracker!B60 -> Dec | O4: Total Days Tracked | P4: =SUM(B5:M5) -> 19
A5: Days Tracked | B5: =COUNTA(Tracker!B7:AJ7) -> 9 | C5: =COUNTA(Tracker!B12:AJ12) -> 2 | D5: =COUNTA(Tracker!B17:AJ17) -> 2 | E5: =COUNTA(Tracker!B22:AJ22) -> 5 | F5: =COUNTA(Tracker!B27:AJ27) -> 0 | G5: =COUNTA(Tracker!B32:AJ32) -> 1 | H5: =COUNTA(Tracker!B37:AJ37) -> 0 | I5: =COUNTA(Tracker!B42:AJ42) -> 0 | J5: =COUNTA(Tracker!B47:AJ47) -> 0 | K5: =COUNTA(Tracker!B52:AJ52) -> 0 | L5: =COUNTA(Tracker!B57:AJ57) -> 0 | M5: =COUNTA(Tracker!B62:AJ62) -> 0 | O5: Total Low Days | P5: =SUM(B8:M8) -> 13
A6: Good Days | B6: =COUNTIF(Tracker!B7:AJ7,"Good") -> 1 | C6: =COUNTIF(Tracker!B12:AJ12,"Good") -> 0 | D6: =COUNTIF(Tracker!B17:AJ17,"Good") -> 0 | E6: =COUNTIF(Tracker!B22:AJ22,"Good") -> 0 | F6: =COUNTIF(Tracker!B27:AJ27,"Good") -> 0 | G6: =COUNTIF(Tracker!B32:AJ32,"Good") -> 1 | H6: =COUNTIF(Tracker!B37:AJ37,"Good") -> 0 | I6: =COUNTIF(Tracker!B42:AJ42,"Good") -> 0 | J6: =COUNTIF(Tracker!B47:AJ47,"Good") -> 0 | K6: =COUNTIF(Tracker!B52:AJ52,"Good") -> 0 | L6: =COUNTIF(Tracker!B57:AJ57,"Good") -> 0 | M6: =COUNTIF(Tracker!B62:AJ62,"Good") -> 0 | O6: Avg Low Days / Cycle | P6: =IFERROR(P5/P7,"-") -> 2.6
A7: Okay Days | B7: =COUNTIF(Tracker!B7:AJ7,"Okay") -> 4 | C7: =COUNTIF(Tracker!B12:AJ12,"Okay") -> 0 | D7: =COUNTIF(Tracker!B17:AJ17,"Okay") -> 0 | E7: =COUNTIF(Tracker!B22:AJ22,"Okay") -> 0 | F7: =COUNTIF(Tracker!B27:AJ27,"Okay") -> 0 | G7: =COUNTIF(Tracker!B32:AJ32,"Okay") -> 0 | H7: =COUNTIF(Tracker!B37:AJ37,"Okay") -> 0 | I7: =COUNTIF(Tracker!B42:AJ42,"Okay") -> 0 | J7: =COUNTIF(Tracker!B47:AJ47,"Okay") -> 0 | K7: =COUNTIF(Tracker!B52:AJ52,"Okay") -> 0 | L7: =COUNTIF(Tracker!B57:AJ57,"Okay") -> 0 | M7: =COUNTIF(Tracker!B62:AJ62,"Okay") -> 0 | O7: Cycles with Data | P7: =COUNTIF(B5:M5,">0") -> 5
A8: Low Days | B8: =COUNTIF(Tracker!B7:AJ7,"Low") -> 4 | C8: =COUNTIF(Tracker!B12:AJ12,"Low") -> 2 | D8: =COUNTIF(Tracker!B17:AJ17,"Low") -> 2 | E8: =COUNTIF(Tracker!B22:AJ22,"Low") -> 5 | F8: =COUNTIF(Tracker!B27:AJ27,"Low") -> 0 | G8: =COUNTIF(Tracker!B32:AJ32,"Low") -> 0 | H8: =COUNTIF(Tracker!B37:AJ37,"Low") -> 0 | I8: =COUNTIF(Tracker!B42:AJ42,"Low") -> 0 | J8: =COUNTIF(Tracker!B47:AJ47,"Low") -> 0 | K8: =COUNTIF(Tracker!B52:AJ52,"Low") -> 0 | L8: =COUNTIF(Tracker!B57:AJ57,"Low") -> 0 | M8: =COUNTIF(Tracker!B62:AJ62,"Low") -> 0 | O8: Most Common Low Phase | P8: {=IFERROR(IF(SUMPRODUCT((Tracker!B3:AJ3="Late Luteal")*(Tracker!B7:AJ7="Low"))+SUMPRODUCT((Tracker!B3:AJ3="Late Luteal")*(Tracker!B12:AJ12="Low"))+SUMPRODUCT((Tracker!B3:AJ3="Late Luteal")*(Tracker!B17:AJ17="Low"))+SUMPRODUCT((Tracker!B3:AJ3="Late Luteal")*(Tracker!B22:AJ22="Low"))+SUMPRODUCT((Tracker!B3:AJ3="Late Luteal")*(Tracker!B27:AJ27="Low"))+SUMPRODUCT((Tracker!B3:AJ3="Late Luteal")*(Tracker!B32:AJ32="Low"))+SUMPRODUCT((Tracker!B3:AJ3="Late Luteal")*(Tracker!B37:AJ37="Low"))+SUMPRODUCT((Tracker!B3:AJ3="Late Luteal")*(Tracker!B42:AJ42="Low"))+SUMPRODUCT((Tracker!B3:AJ3="Late Luteal")*(Tracker!B47:AJ47="Low"))+SUMPRODUCT((Tracker!B3:AJ3="Late Luteal")*(Tracker!B52:AJ52="Low"))+SUMPRODUCT((Tracker!B3:AJ3="Late Luteal")*(Tracker!B57:AJ57="Low"))+SUMPRODUCT((Tracker!B3:AJ3="Late Luteal")*(Tracker!B62:AJ62="Low"))>=SUMPRODUCT((Tracker!B3:AJ3="Follicular")*(Tracker!B7:AJ7="Low"))+SUMPRODUCT((Tracker!B3:AJ3="Follicular")*(Tracker!B12:AJ12="Low"))+SUMPRODUCT((Tracker!B3:AJ3="Follicular")*(Tracker!B17:AJ17="Low"))+SUMPRODUCT((Tracker!B3:AJ3="Follicular")*(Tracker!B22:AJ22="Low"))+SUMPRODUCT((Tracker!B3:AJ3="Follicular")*(Tracker!B27:AJ27="Low"))+SUMPRODUCT((Tracker!B3:AJ3="Follicular")*(Tracker!B32:AJ32="Low"))+SUMPRODUCT((Tracker!B3:AJ3="Follicular")*(Tracker!B37:AJ37="Low"))+SUMPRODUCT((Tracker!B3:AJ3="Follicular")*(Tracker!B42:AJ42="Low"))+SUMPRODUCT((Tracker!B3:AJ3="Follicular")*(Tracker!B47:AJ47="Low"))+SUMPRODUCT((Tracker!B3:AJ3="Follicular")*(Tracker!B52:AJ52="Low"))+SUMPRODUCT((Tracker!B3:AJ3="Follicular")*(Tracker!B57:AJ57="Low"))+SUMPRODUCT((Tracker!B3:AJ3="Follicular")*(Tracker!B62:AJ62="Low")),"Late Luteal","Follicular"),"-")} -> Late Luteal
A9: % Low in Late Luteal | B9: =IFERROR(COUNTIFS(Tracker!B7:AJ7,"Low",Tracker!B3:AJ3,"Late Luteal")/COUNTIF(Tracker!B3:AJ3,"Late Luteal"),"-") -> 0 | C9: =IFERROR(COUNTIFS(Tracker!B12:AJ12,"Low",Tracker!B3:AJ3,"Late Luteal")/COUNTIF(Tracker!B3:AJ3,"Late Luteal"),"-") -> 0.2 | D9: =IFERROR(COUNTIFS(Tracker!B17:AJ17,"Low",Tracker!B3:AJ3,"Late Luteal")/COUNTIF(Tracker!B3:AJ3,"Late Luteal"),"-") -> 0.2 | E9: =IFERROR(COUNTIFS(Tracker!B22:AJ22,"Low",Tracker!B3:AJ3,"Late Luteal")/COUNTIF(Tracker!B3:AJ3,"Late Luteal"),"-") -> 0.2 | F9: =IFERROR(COUNTIFS(Tracker!B27:AJ27,"Low",Tracker!B3:AJ3,"Late Luteal")/COUNTIF(Tracker!B3:AJ3,"Late Luteal"),"-") -> 0 | G9: =IFERROR(COUNTIFS(Tracker!B32:AJ32,"Low",Tracker!B3:AJ3,"Late Luteal")/COUNTIF(Tracker!B3:AJ3,"Late Luteal"),"-") -> 0 | H9: =IFERROR(COUNTIFS(Tracker!B37:AJ37,"Low",Tracker!B3:AJ3,"Late Luteal")/COUNTIF(Tracker!B3:AJ3,"Late Luteal"),"-") -> 0 | I9: =IFERROR(COUNTIFS(Tracker!B42:AJ42,"Low",Tracker!B3:AJ3,"Late Luteal")/COUNTIF(Tracker!B3:AJ3,"Late Luteal"),"-") -> 0 | J9: =IFERROR(COUNTIFS(Tracker!B47:AJ47,"Low",Tracker!B3:AJ3,"Late Luteal")/COUNTIF(Tracker!B3:AJ3,"Late Luteal"),"-") -> 0 | K9: =IFERROR(COUNTIFS(Tracker!B52:AJ52,"Low",Tracker!B3:AJ3,"Late Luteal")/COUNTIF(Tracker!B3:AJ3,"Late Luteal"),"-") -> 0 | L9: =IFERROR(COUNTIFS(Tracker!B57:AJ57,"Low",Tracker!B3:AJ3,"Late Luteal")/COUNTIF(Tracker!B3:AJ3,"Late Luteal"),"-") -> 0 | M9: =IFERROR(COUNTIFS(Tracker!B62:AJ62,"Low",Tracker!B3:AJ3,"Late Luteal")/COUNTIF(Tracker!B3:AJ3,"Late Luteal"),"-") -> 0
A10: % Low in Follicular | B10: =IFERROR(COUNTIFS(Tracker!B7:AJ7,"Low",Tracker!B3:AJ3,"Follicular")/COUNTIF(Tracker!B3:AJ3,"Follicular"),"-") -> 0 | C10: =IFERROR(COUNTIFS(Tracker!B12:AJ12,"Low",Tracker!B3:AJ3,"Follicular")/COUNTIF(Tracker!B3:AJ3,"Follicular"),"-") -> 0 | D10: =IFERROR(COUNTIFS(Tracker!B17:AJ17,"Low",Tracker!B3:AJ3,"Follicular")/COUNTIF(Tracker!B3:AJ3,"Follicular"),"-") -> 0 | E10: =IFERROR(COUNTIFS(Tracker!B22:AJ22,"Low",Tracker!B3:AJ3,"Follicular")/COUNTIF(Tracker!B3:AJ3,"Follicular"),"-") -> 0 | F10: =IFERROR(COUNTIFS(Tracker!B27:AJ27,"Low",Tracker!B3:AJ3,"Follicular")/COUNTIF(Tracker!B3:AJ3,"Follicular"),"-") -> 0 | G10: =IFERROR(COUNTIFS(Tracker!B32:AJ32,"Low",Tracker!B3:AJ3,"Follicular")/COUNTIF(Tracker!B3:AJ3,"Follicular"),"-") -> 0 | H10: =IFERROR(COUNTIFS(Tracker!B37:AJ37,"Low",Tracker!B3:AJ3,"Follicular")/COUNTIF(Tracker!B3:AJ3,"Follicular"),"-") -> 0 | I10: =IFERROR(COUNTIFS(Tracker!B42:AJ42,"Low",Tracker!B3:AJ3,"Follicular")/COUNTIF(Tracker!B3:AJ3,"Follicular"),"-") -> 0 | J10: =IFERROR(COUNTIFS(Tracker!B47:AJ47,"Low",Tracker!B3:AJ3,"Follicular")/COUNTIF(Tracker!B3:AJ3,"Follicular"),"-") -> 0 | K10: =IFERROR(COUNTIFS(Tracker!B52:AJ52,"Low",Tracker!B3:AJ3,"Follicular")/COUNTIF(Tracker!B3:AJ3,"Follicular"),"-") -> 0 | L10: =IFERROR(COUNTIFS(Tracker!B57:AJ57,"Low",Tracker!B3:AJ3,"Follicular")/COUNTIF(Tracker!B3:AJ3,"Follicular"),"-") -> 0 | M10: =IFERROR(COUNTIFS(Tracker!B62:AJ62,"Low",Tracker!B3:AJ3,"Follicular")/COUNTIF(Tracker!B3:AJ3,"Follicular"),"-") -> 0 | O10: YOUR PATTERNS SO FAR
O11: Cycles Tracked | P11: =P7 -> 5
A12: PATTERNS ACROSS YOUR CYCLES | O12: Cycles Showing This Pattern | P12: =COUNTIF(B15:M15,"YES") -> 3
A13: Low mood in late luteal phase? | B13: =IF(B5=0,"",IF(COUNTIFS(Tracker!B7:AJ7,"Low",Tracker!B3:AJ3,"Late Luteal")>0,"YES","NO")) -> NO | C13: =IF(C5=0,"",IF(COUNTIFS(Tracker!B12:AJ12,"Low",Tracker!B3:AJ3,"Late Luteal")>0,"YES","NO")) -> YES | D13: =IF(D5=0,"",IF(COUNTIFS(Tracker!B17:AJ17,"Low",Tracker!B3:AJ3,"Late Luteal")>0,"YES","NO")) -> YES | E13: =IF(E5=0,"",IF(COUNTIFS(Tracker!B22:AJ22,"Low",Tracker!B3:AJ3,"Late Luteal")>0,"YES","NO")) -> YES | F13: =IF(F5=0,"",IF(COUNTIFS(Tracker!B27:AJ27,"Low",Tracker!B3:AJ3,"Late Luteal")>0,"YES","NO")) | G13: =IF(G5=0,"",IF(COUNTIFS(Tracker!B32:AJ32,"Low",Tracker!B3:AJ3,"Late Luteal")>0,"YES","NO")) -> NO | H13: =IF(H5=0,"",IF(COUNTIFS(Tracker!B37:AJ37,"Low",Tracker!B3:AJ3,"Late Luteal")>0,"YES","NO")) | I13: =IF(I5=0,"",IF(COUNTIFS(Tracker!B42:AJ42,"Low",Tracker!B3:AJ3,"Late Luteal")>0,"YES","NO")) | J13: =IF(J5=0,"",IF(COUNTIFS(Tracker!B47:AJ47,"Low",Tracker!B3:AJ3,"Late Luteal")>0,"YES","NO")) | K13: =IF(K5=0,"",IF(COUNTIFS(Tracker!B52:AJ52,"Low",Tracker!B3:AJ3,"Late Luteal")>0,"YES","NO")) | L13: =IF(L5=0,"",IF(COUNTIFS(Tracker!B57:AJ57,"Low",Tracker!B3:AJ3,"Late Luteal")>0,"YES","NO")) | M13: =IF(M5=0,"",IF(COUNTIFS(Tracker!B62:AJ62,"Low",Tracker!B3:AJ3,"Late Luteal")>0,"YES","NO")) | O13: How Often | P13: =IFERROR(P12/P11,"-") -> 0.6
A14: Clear in follicular phase? | B14: =IF(B5=0,"",IF(COUNTIFS(Tracker!B7:AJ7,"Low",Tracker!B3:AJ3,"Follicular")=0,"YES","NO")) -> YES | C14: =IF(C5=0,"",IF(COUNTIFS(Tracker!B12:AJ12,"Low",Tracker!B3:AJ3,"Follicular")=0,"YES","NO")) -> YES | D14: =IF(D5=0,"",IF(COUNTIFS(Tracker!B17:AJ17,"Low",Tracker!B3:AJ3,"Follicular")=0,"YES","NO")) -> YES | E14: =IF(E5=0,"",IF(COUNTIFS(Tracker!B22:AJ22,"Low",Tracker!B3:AJ3,"Follicular")=0,"YES","NO")) -> YES | F14: =IF(F5=0,"",IF(COUNTIFS(Tracker!B27:AJ27,"Low",Tracker!B3:AJ3,"Follicular")=0,"YES","NO")) | G14: =IF(G5=0,"",IF(COUNTIFS(Tracker!B32:AJ32,"Low",Tracker!B3:AJ3,"Follicular")=0,"YES","NO")) -> YES | H14: =IF(H5=0,"",IF(COUNTIFS(Tracker!B37:AJ37,"Low",Tracker!B3:AJ3,"Follicular")=0,"YES","NO")) | I14: =IF(I5=0,"",IF(COUNTIFS(Tracker!B42:AJ42,"Low",Tracker!B3:AJ3,"Follicular")=0,"YES","NO")) | J14: =IF(J5=0,"",IF(COUNTIFS(Tracker!B47:AJ47,"Low",Tracker!B3:AJ3,"Follicular")=0,"YES","NO")) | K14: =IF(K5=0,"",IF(COUNTIFS(Tracker!B52:AJ52,"Low",Tracker!B3:AJ3,"Follicular")=0,"YES","NO")) | L14: =IF(L5=0,"",IF(COUNTIFS(Tracker!B57:AJ57,"Low",Tracker!B3:AJ3,"Follicular")=0,"YES","NO")) | M14: =IF(M5=0,"",IF(COUNTIFS(Tracker!B62:AJ62,"Low",Tracker!B3:AJ3,"Follicular")=0,"YES","NO"))
A15: Both seen this cycle? | B15: =IF(B5=0,"",IF(AND(B13="YES",B14="YES"),"YES","NO")) -> NO | C15: =IF(C5=0,"",IF(AND(C13="YES",C14="YES"),"YES","NO")) -> YES | D15: =IF(D5=0,"",IF(AND(D13="YES",D14="YES"),"YES","NO")) -> YES | E15: =IF(E5=0,"",IF(AND(E13="YES",E14="YES"),"YES","NO")) -> YES | F15: =IF(F5=0,"",IF(AND(F13="YES",F14="YES"),"YES","NO")) | G15: =IF(G5=0,"",IF(AND(G13="YES",G14="YES"),"YES","NO")) -> NO | H15: =IF(H5=0,"",IF(AND(H13="YES",H14="YES"),"YES","NO")) | I15: =IF(I5=0,"",IF(AND(I13="YES",I14="YES"),"YES","NO")) | ... M15: =IF(M5=0,"",IF(AND(M13="YES",M14="YES"),"YES","NO")) | O15: What You've Recorded | P15: =IF(P11<2,"Keep tracking",IF(P13>=0.5,"A recurring pattern was recorded",IF(P13>=0.25,"A pattern may be emerging","No clear pattern yet"))) -> A recurring pattern was recorded
O16: Suggested Next Step | P16: =IF(P11<2,"Track at least 2 full cycles to see a clearer picture",IF(P13>=0.5,"This could be worth discussing with your doctor — bring this tracker along",IF(P13>=0.25,"Keep tracking to see if the pattern continues","Keep tracking — patterns often take a few cycles to show"))) -> This could be worth discussing with your doctor — bring this tracker along
A17: A NOTE ON THIS DASHBOARD
A18: Your dashboard helps you see your symptoms and patterns across your cycle. Use what you notice as a starting point for conversations with your healthcare professional. Dear PMDD is a symptom-tracking tool, not a diagnostic tool or a substitute for medical advice.

Sheet FAQ
B1: FAQ
B3: How do I get started?
B4: Go to the Setup tab and enter your cycle start date, average cycle length, and period length. The Tracker tab will automatically generate dates, phases, and month blocks. Then just start logging your mood each day using the dropdown in the Mood row — choose Good, Okay, or Low.
B6: What if my ovulation day is different from what the tracker shows?
B7: The stage row (Period, Follicular, Ovulation, Mid Luteal, Late Luteal) is calculated from your average cycle length as a general guide. Real cycles vary — ovulation can shift by several days. If you know your actual ovulation day for a particular month, note it in the Notes row for that cycle (e.g. "Ovulated day 12"). The Dashboard doesn't depend on the stage labels being perfectly accurate — it uses the Late Luteal and Follicular windows from your typical cycle length as an approximation.
B9: What does the Dashboard show me about patterns?
B10: The Dashboard looks for a specific pattern across your tracked cycles: do your Low moods tend to appear in the Late Luteal phase (the last ~5 days before your period) and ease off during the Follicular phase (after your period ends)? This is a pattern many people with PMDD notice. The Dashboard summarises how often this pattern shows up across your tracked cycles — it's a starting point for reflection, not a result to self-diagnose from: • No clear pattern yet — less than 25% of tracked cycles show it • A pattern may be emerging — 25–49% of cycles show it • A recurring pattern — 50% or more of cycles show it
B12: Is this a medical diagnosis?
B13: No. This tracker is a personal tool to help you spot patterns — it is not a medical diagnosis and cannot confirm or rule out PMDD. Only a healthcare professional can assess that, typically using daily symptom ratings tracked over at least 2 menstrual cycles. If you notice a recurring pattern here, we'd encourage speaking with your doctor. Bring this tracker to your appointment — it gives them a clear, concrete record to work from.
B15: How many cycles do I need to track?
B16: We'd suggest at least 2 full cycles before looking for patterns on the Dashboard — the more cycles you track, the clearer the picture becomes. The tracker supports up to 12 cycles.
B18: What do the colours on the Tracker mean?
... B43: That's exactly what this tracker is for. Log your mood daily for a few cycles without worrying about the cause — the Dashboard will help you see whether a pattern lines up with your cycle or not. If nothing lines up, that's useful information too. Either way, bring what you've noticed to your doctor and let them help you make sense of it alongside anything else that's going on.

Sheet Your Doctor Visit
B1: Your Doctor Visit
B3: If you've noticed a recurring pattern, the next step is a conversation with your healthcare professional. This can feel daunting — many people struggle to put what they're experiencing into words. This guide will help you prepare and communicate clearly.
B5: BEFORE YOUR APPOINTMENT
B7: 1. Track at least 2 full cycles
B8: A record kept in real time is often easier to talk through than something recalled from memory. Even a couple of tracked cycles showing a pattern gives you something concrete to work with. Log your mood every day, even on good days — knowing when things ease off is just as useful as knowing when they don't.
B10: 2. Print or save your Dashboard
B11: Before your appointment, print the Dashboard tab or save it as a PDF. This gives you a one-page summary of your cycle-by-cycle mood pattern and what you've noticed. A clear visual summary can be easier to talk through than describing months of symptoms from memory.
B13: 3. Write down your key symptoms
B14: Beyond mood, you might notice things like irritability, anxiety, feeling overwhelmed, fatigue, difficulty concentrating, sleep changes, or appetite changes. Note which ones you experience and roughly when in your cycle they appear. Your Notes row on the Tracker is a good place to review this before your appointment.
B16: WHAT TO SAY
B18: Opening the conversation
B19: You don't need medical language. Try something like: “I've been tracking my mood against my menstrual cycle for the past few months because I noticed a pattern. I feel worse in the week before my period — [your symptoms] — and it eases once my period starts. I've been using a tracker and I'd like to show you what I found.”
... B45: 💛 Remember: You've recorded what you've experienced. Now you have something concrete to take into the conversation.

Sheet Symptom Pattern Report
B2: FOR YOUR DOCTOR
B3: • Symptom Pattern Report
B8: WHAT YOU'VE RECORDED | P8: CYCLES | W8: DAYS LOGGED
B10: ="Across "&COUNTIF(Dashboard!B5:D5,">0")&" prospectively-tracked cycle"&IF(COUNTIF(Dashboard!B5:D5,">0")=1,"","s")&", low mood was recorded in the late luteal phase and eased during the follicular phase in "&COUNTIF(Dashboard!B13:D13,"YES")&" of "&COUNTIF(Dashboard!B5:D5,">0")&" cycles ("&TEXT(IFERROR(COUNTIF(Dashboard!B13:D13,"YES")/COUNTIF(Dashboard!B5:D5,">0"),0),"0%")&")." -> Across 3 prospectively-tracked cycles, low mood was recorded in the late luteal phase and eased during the follicular phase in 2 of 3 cycles (67%). | P10: =COUNTIF(Dashboard!B5:D5,">0") -> 3 | W10: =SUM(Dashboard!B5:D5) -> 13
P13: LOW DAYS | W13: PHASES RECORDED
P15: =SUM(Dashboard!B8:D8) -> 8 | W15: =COUNTIF(Dashboard!B13:D13,"YES")&"/"&COUNTIF(Dashboard!B5:D5,">0") -> 2/3
B16: ="What you've recorded: "&IF(COUNTIF(Dashboard!B5:D5,">0")<2,"Not enough data yet to describe a trend.","Symptoms were recorded more frequently during the late luteal phase in "&COUNTIF(Dashboard!B13:D13,"YES")&" of "&COUNTIF(Dashboard!B5:D5,">0")&" tracked cycles. Continue tracking, and bring this record to your healthcare professional to discuss.") -> What you've recorded: Symptoms were recorded more frequently during the late luteal phase in 2 of 3 tracked cycles. Continue tracking, and bring this record to your healthcare professional to discuss.
B19: DAILY MOOD, ALIGNED BY CYCLE DAY
D21: =Tracker!B3 -> Period | E21: =Tracker!C3 -> Period | F21: =Tracker!D3 -> Period | G21: =Tracker!E3 -> Period | H21: =Tracker!F3 -> Period | I21: =Tracker!G3 -> Follicular | J21: =Tracker!H3 -> Follicular | K21: =Tracker!I3 -> Follicular | ... AE21: =Tracker!AC3 -> Late Luteal
B23: CYCLE 1 | D23: =IFERROR(IF(Tracker!B7="","",Tracker!B7),"") -> Good | E23: =IFERROR(IF(Tracker!C7="","",Tracker!C7),"") -> Okay | F23: =IFERROR(IF(Tracker!D7="","",Tracker!D7),"") -> Low | G23: =IFERROR(IF(Tracker!E7="","",Tracker!E7),"") | H23: =IFERROR(IF(Tracker!F7="","",Tracker!F7),"") | I23: =IFERROR(IF(Tracker!G7="","",Tracker!G7),"") | J23: =IFERROR(IF(Tracker!H7="","",Tracker!H7),"") | K23: =IFERROR(IF(Tracker!I7="","",Tracker!I7),"") | ... AE23: =IFERROR(IF(Tracker!AC7="","",Tracker!AC7),"")
B25: CYCLE 2 | D25: =IFERROR(IF(Tracker!B12="","",Tracker!B12),"") | E25: =IFERROR(IF(Tracker!C12="","",Tracker!C12),"") | F25: =IFERROR(IF(Tracker!D12="","",Tracker!D12),"") | G25: =IFERROR(IF(Tracker!E12="","",Tracker!E12),"") | H25: =IFERROR(IF(Tracker!F12="","",Tracker!F12),"") | I25: =IFERROR(IF(Tracker!G12="","",Tracker!G12),"") | J25: =IFERROR(IF(Tracker!H12="","",Tracker!H12),"") | K25: =IFERROR(IF(Tracker!I12="","",Tracker!I12),"") | ... AE25: =IFERROR(IF(Tracker!AC12="","",Tracker!AC12),"")
B27: CYCLE 3 | D27: =IFERROR(IF(Tracker!B17="","",Tracker!B17),"") | E27: =IFERROR(IF(Tracker!C17="","",Tracker!C17),"") | F27: =IFERROR(IF(Tracker!D17="","",Tracker!D17),"") | G27: =IFERROR(IF(Tracker!E17="","",Tracker!E17),"") | H27: =IFERROR(IF(Tracker!F17="","",Tracker!F17),"") | I27: =IFERROR(IF(Tracker!G17="","",Tracker!G17),"") | J27: =IFERROR(IF(Tracker!H17="","",Tracker!H17),"") | K27: =IFERROR(IF(Tracker!I17="","",Tracker!I17),"") | ... AE27: =IFERROR(IF(Tracker!AC17="","",Tracker!AC17),"")
D30: GOOD | H30: OKAY | L30: LOW | Q30: SHADED STRIP — PHASE: Period · Follicular · Ovulation · Mid Luteal · Late Luteal
B34: HOW TO OPEN THE CONVERSATION | Q34: WHAT YOU'VE RECORDED
B36: "I've tracked my mood against my cycle for three months. Here's what I've recorded: I feel worse in the week before my period, and it eases once my period starts. I'd like to talk through what this could mean." | Q36: Daily ratings logged, 2+ cycles | AA36: =IF(Dashboard!P11>=2,"SEEN ✓","NOT YET") -> SEEN ✓
Q38: Low mood recorded in late luteal phase | AA38: =IF(COUNTIF(Dashboard!B13:M13,"YES")>=1,"SEEN ✓","NOT YET") -> SEEN ✓
Q40: Mood eased in follicular phase | AA40: =IF(COUNTIF(Dashboard!B14:M14,"YES")>=1,"SEEN ✓","NOT YET") -> SEEN ✓
Q42: Bring this to your appointment | AA42: DISCUSS IN VISIT
B45: QUESTIONS WORTH ASKING
B47: 1. What do you make of the pattern I've recorded? | P47: 2. Are there other possible explanations I should consider?
B49: 3. What would I like to discuss about these patterns? | P49: 4. What questions do I have about what I'm experiencing?
B51: 5. Are there lifestyle changes that might help meanwhile? | P51: 6. How many more cycles should I track before we revisit?
B55: SYMPTOM-TRACKING TOOL · NOT A MEDICAL DIAGNOSIS · SELF-REPORTED DATA | P55: DEAR PMDD · PAGE 1 OF 1
